<?xml version="1.0" encoding="utf-8"?>
<robot name="adr_description" xmlns:xacro="http://ros.org/wiki/xacro">
  <xacro:include filename="adr_description/urdf/adr_description.gazebo.xacro" />

  <!-- base -->
  <!-- <link name="base_footprint" />

  <joint name="base_joint" type="fixed">
    <parent link="base_footprint" />
    <child link="body" />
    <origin xyz="0.0 0.0 0.010" rpy="0 0 0" />
  </joint> -->

  <!-- body-->
  <link name="body">
    <inertial>
      <origin xyz="0.002527 0.014122 2.6333E-08" rpy="0 0 0" />
      <mass value="25" />
      <inertia ixx="2.0665" ixy="0" ixz="0" iyy="3.4602" iyz="0" izz="5.0679" />
    </inertial>
    <visual>
      <origin xyz="0 0 0" rpy="0 0 0" />
      <geometry>
        <mesh filename="package://adr_description/meshes/body.STL" />
      </geometry>
      <material name="">
        <color rgba="0.79216 0.81961 0.93333 1" />
      </material>
    </visual>
    <collision>
      <origin xyz="0 0 0" rpy="0 0 0" />
      <geometry>
        <mesh filename="package://adr_description/meshes/body.STL" />
      </geometry>
    </collision>
  </link>

  

  <link name="front_right_wheel_link">
    <inertial>
      <origin xyz="0 0 0.025" rpy="0 0 0" />
      <mass value="0.5" />
      <inertia ixx="0.000851" ixy="0" ixz="0" iyy="0.000851" iyz="0" izz="0.001513" />
    </inertial>
    <visual>
      <origin xyz="0 0 0" rpy="0 0 0" />
      <geometry>
        <mesh filename="package://adr_description/meshes/front_right_wheel_link.STL" />
      </geometry>
      <material name="">
        <color rgba="0.79216 0.81961 0.93333 1" />
      </material>
    </visual>
    <collision>
      <origin xyz="0 0 0" rpy="0 0 0" />
      <geometry>
        <mesh filename="package://adr_description/meshes/front_right_wheel_link.STL" />
      </geometry>
    </collision>
  </link>

  <joint name="front_right_wheel_joint" type="continuous">
    <origin xyz="0.355 -0.295 -0.145" rpy="1.5708 -0.51499 0" />
    <parent link="body" />
    <child link="front_right_wheel_link" />
    <axis xyz="0 0 1" />
  </joint>

  <link name="front_left_wheel_link">
    <inertial>
      <origin xyz="0 0 -0.025" rpy="0 0 0" />
      <mass value="0.5" />
      <inertia ixx="0.000851" ixy="0" ixz="0" iyy="0.000851" iyz="0" izz="0.001513" />
    </inertial>
    <visual>
      <origin xyz="0 0 0" rpy="0 0 0" />
      <geometry>
        <mesh filename="package://adr_description/meshes/front_left_wheel_link.STL" />
      </geometry>
      <material name="">
        <color rgba="0.79216 0.81961 0.93333 1" />
      </material>
    </visual>
    <collision>
      <origin xyz="0 0 0" rpy="0 0 0" />
      <geometry>
        <mesh filename="package://adr_description/meshes/front_left_wheel_link.STL" />
      </geometry>
    </collision>
  </link>

  <joint name="front_left_wheel_joint" type="continuous">
    <origin xyz="0.355 0.295 -0.145" rpy="1.5708 -0.010202 0" />
    <parent link="body" />
    <child link="front_left_wheel_link" />
    <axis xyz="0 0 1" />
  </joint>

    <!-- rear wheels -->
  <link name="rear_right_wheel_holder_link">
    <inertial>
      <origin xyz="0.019738 -0.017918 4.8612E-10" rpy="0 0 0" />
      <mass value="0.125" />
      <inertia ixx="5.8E-05" ixy="0" ixz="0" iyy="9.6E-05" iyz="0" izz="0.000104" />
    </inertial>
    <visual>
      <origin xyz="0 0 0" rpy="0 0 0" />
      <geometry>
        <mesh filename="package://adr_description/meshes/rear_right_wheel_holder_link.STL" />
      </geometry>
      <material name="">
        <color rgba="0.77647 0.75686 0.73725 1" />
      </material>
    </visual>
    <collision>
      <origin xyz="0 0 0" rpy="0 0 0" />
      <geometry>
        <mesh filename="package://adr_description/meshes/rear_right_wheel_holder_link.STL" />
      </geometry>
    </collision>
  </link>

  <joint name="rear_right_wheel_holder_joint" type="continuous">
    <origin xyz="-0.31 -0.215 -0.118" rpy="1.5708 0 3.1416" />
    <parent link="body" />
    <child link="rear_right_wheel_holder_link" />
    <axis xyz="0 1 0" />
  </joint>

  <link name="rear_right_wheel_link">
    <inertial>
      <origin xyz="1.1102E-16 -0.01 1.1102E-16" rpy="0 0 0" />
      <mass value="0.25" />
      <inertia ixx="0.000122" ixy="0" ixz="0" iyy="0.000122" iyz="0" izz="0.000201" />
    </inertial>
    <visual>
      <origin xyz="0 0 0" rpy="0 0 0" />
      <geometry>
        <mesh filename="package://adr_description/meshes/rear_right_wheel_link.STL" />
      </geometry>
      <material name="">
        <color rgba="0.79216 0.81961 0.93333 1" />
      </material>
    </visual>
    <collision>
      <origin xyz="0 0 0" rpy="0 0 0" />
      <geometry>
        <mesh filename="package://adr_description/meshes/rear_right_wheel_link.STL" />
      </geometry>
    </collision>
  </link>

  <joint name="rear_right_wheel_joint" type="continuous">
    <origin xyz="0.047511 -0.075249 0" rpy="3.1416 0 1.0182" />
    <parent link="rear_right_wheel_holder_link" />
    <child link="rear_right_wheel_link" />
    <axis xyz="0 0 1" />
  </joint>

  <link name="rear_left_wheel_holder_link">
    <inertial>
      <origin xyz="0.019738 -0.017918 4.8612E-10" rpy="0 0 0" />
      <mass value="0.125" />
      <inertia ixx="5.8E-05" ixy="0" ixz="0" iyy="9.6E-05" iyz="0" izz="0.000104" />
    </inertial>
    <visual>
      <origin xyz="0 0 0" rpy="0 0 0" />
      <geometry>
        <mesh filename="package://adr_description/meshes/rear_left_wheel_holder_link.STL" />
      </geometry>
      <material name="">
        <color rgba="0.77647 0.75686 0.73725 1" />
      </material>
    </visual>
    <collision>
      <origin xyz="0 0 0" rpy="0 0 0" />
      <geometry>
        <mesh filename="package://adr_description/meshes/rear_left_wheel_holder_link.STL" />
      </geometry>
    </collision>
  </link>

  <joint name="rear_left_wheel_holder_joint" type="continuous">
    <origin xyz="-0.31 0.215 -0.118" rpy="1.5708 0 3.1416" />
    <parent link="body" />
    <child link="rear_left_wheel_holder_link" />
    <axis xyz="0 1 0" />
  </joint>

  <link name="rear_left_wheel_link">
    <inertial>
      <origin xyz="2.7756E-17 -0.01 2.7756E-17" rpy="0 0 0" />
      <mass value="0.15829" />
      <inertia ixx="0.000122" ixy="0" ixz="0" iyy="0.000122" iyz="0" izz="0.000201" />
    </inertial>
    <visual>
      <origin xyz="0 0 0" rpy="0 0 0" />
      <geometry>
        <mesh filename="package://adr_description/meshes/rear_left_wheel_link.STL" />
      </geometry>
      <material name="">
        <color rgba="0.79216 0.81961 0.93333 1" />
      </material>
    </visual>
    <collision>
      <origin xyz="0 0 0" rpy="0 0 0" />
      <geometry>
        <mesh filename="package://adr_description/meshes/rear_left_wheel_link.STL" />
      </geometry>
    </collision>
  </link>

  <joint name="rear_left_wheel_joint" type="continuous">
    <origin xyz="0.045998 -0.077143 0" rpy="3.1416 0 0.77512" />
    <parent link="rear_left_wheel_holder_link" />
    <child link="rear_left_wheel_link" />
    <axis xyz="0 0 1" />
  </joint>

  <link name="zed_link">
    <inertial>
      <origin xyz="4.4834E-10 4.3912E-06 0.015479" rpy="0 0 0" />
      <mass value="0.1" />
      <inertia ixx="1.5E-05" ixy="0" ixz="0" iyy="0.000245" iyz="0" izz="0.000247" />
    </inertial>
    <visual>
      <origin xyz="0 0 0" rpy="0 0 0" />
      <geometry>
        <mesh filename="package://adr_description/meshes/zed_link.STL" />
      </geometry>
      <material name="">
        <color rgba="0.79216 0.81961 0.93333 1" />
      </material>
    </visual>
    <collision>
      <origin xyz="0 0 0" rpy="0 0 0" />
      <geometry>
        <mesh filename="package://adr_description/meshes/zed_link.STL" />
      </geometry>
    </collision>
  </link>

  <joint name="zed_joint" type="fixed">
    <origin xyz="0.4816 0.00048374 0.079104" rpy="1.5708 -0.00010913 1.5708" />
    <parent link="body" />
    <child link="zed_link" />
    <axis xyz="0 0 0" />
  </joint>

  <link name="touch_screen_holder_link">
    <inertial>
      <origin xyz="0.0050744 0.027898 -8.9499E-17" rpy="0 0 0" />
      <mass value="0.02" />
      <inertia ixx="1E-06" ixy="0" ixz="0" iyy="6E-06" iyz="0" izz="6E-06" />
    </inertial>
    <visual>
      <origin xyz="0 0 0" rpy="0 0 0" />
      <geometry>
        <mesh filename="package://adr_description/meshes/touch_screen_holder_link.STL" />
      </geometry>
      <material name="">
        <color rgba="0.89412 0.91373 0.92941 1" />
      </material>
    </visual>
    <collision>
      <origin xyz="0 0 0" rpy="0 0 0" />
      <geometry>
        <mesh filename="package://adr_description/meshes/touch_screen_holder_link.STL" />
      </geometry>
    </collision>
  </link>

  <joint name="touch_screen_holder_joint" type="fixed">
    <origin xyz="0.49421 0 0.23821" rpy="-1.5708 0.7854 0" />
    <parent link="body" />
    <child link="touch_screen_holder_link" />
    <axis xyz="0 0 0" />
  </joint>

  <link name="touchscreen_link">
    <inertial>
      <origin xyz="6.0462E-14 -0.0099994 0.0074779" rpy="0 0 0" />
      <mass value="0.4" />
      <inertia ixx="0.001129" ixy="0" ixz="0" iyy="0.002357" iyz="0" izz="0.003467" />
    </inertial>
    <visual>
      <origin xyz="0 0 0" rpy="0 0 0" />
      <geometry>
        <mesh filename="package://adr_description/meshes/touchscreen_link.STL" />
      </geometry>
      <material name="">
        <color rgba="0.79216 0.81961 0.93333 1" />
      </material>
    </visual>
    <collision>
      <origin xyz="0 0 0" rpy="0 0 0" />
      <geometry>
        <mesh filename="package://adr_description/meshes/touchscreen_link.STL" />
      </geometry>
    </collision>
  </link>

  <joint name="touchscreen_joint" type="fixed">
    <origin xyz="-0.01 -0.015001 0" rpy="1.5707 -1.5708 0" />
    <parent link="touch_screen_holder_link" />
    <child link="touchscreen_link" />
    <axis xyz="0 0 0" />
  </joint>

  <link name="load_link">
    <inertial>
      <origin xyz="-1.4311E-17 5.5511E-17 7.3581E-17" rpy="0 0 0" />
      <mass value="12" />
      <inertia ixx="0.52" ixy="0" ixz="0" iyy="0.8" iyz="0" izz="1" />
    </inertial>
    <visual>
      <origin xyz="0 0 0" rpy="0 0 0" />
      <geometry>
        <mesh filename="package://adr_description/meshes/load_link.STL" />
      </geometry>
      <material name="">
        <color rgba="0.79216 0.81961 0.93333 1" />
      </material>
    </visual>
    <collision>
      <origin xyz="0 0 0" rpy="0 0 0" />
      <geometry>
        <mesh filename="package://adr_description/meshes/load_link.STL" />
      </geometry>
    </collision>
  </link>

  <joint name="load_joint" type="fixed">
    <origin xyz="0 0 0.18" rpy="1.5708 0 0" />
    <parent link="body" />
    <child link="load_link" />
    <axis xyz="0 0 0" />
  </joint>

   <!-- caster back -->
   <joint name="caster_back_joint" type="fixed">
    <parent link="body" />
    <child link="caster_back" />
    <origin xyz="-0.081 0 -0.004" rpy="-1.57 0 0" />
  </joint>

  <link name="caster_back">
    <collision>
      <origin xyz="0 0.001 0" rpy="0 0 0" />
      <geometry>
        <box size="0.030 0.009 0.020" />
      </geometry>
    </collision>

    <inertial>
      <origin xyz="0 0 0" />
      <mass value="0.005" />
      <inertia ixx="0.001" ixy="0.0" ixz="0.0" iyy="0.001" iyz="0.0" izz="0.001" />
    </inertial>
  </link>

  <!-- imu -->
  <joint name="imu_sensor_joint" type="fixed">
    <parent link="body" />
    <child link="imu_sensor" />
    <origin xyz="-0.032 0 0.068" rpy="0 0 0" />
  </joint>

  <link name="imu_sensor" />

  <!-- lidar -->
  <joint name="scan_joint" type="fixed">
    <parent link="body" />
    <child link="base_scan" />
    <origin xyz="-0.032 0 0.30" rpy="0 0 0" />
  </joint>

  <link name="base_scan">

    <visual>
      <origin xyz="0 0 0.0" rpy="0 0 0" />
      <geometry>
        <mesh filename="package://adr_description/meshes/lds.STL" scale="0.001 0.001 0.001" />
      </geometry>
      <material name="dark" />
    </visual>

    <collision>
      <origin xyz="0.015 0 -0.0065" rpy="0 0 0" />
      <geometry>
        <cylinder length="0.0315" radius="0.055" />
      </geometry>
    </collision>

    <inertial>
      <mass value="0.114" />
      <origin xyz="0 0 0" />
      <inertia ixx="0.001" ixy="0.0" ixz="0.0" iyy="0.001" iyz="0.0" izz="0.001" />
    </inertial>
    
  </link>


   <!-- Colors
  <material name="black">
    <color rgba="0.0 0.0 0.0 1.0" />
  </material>

  <material name="dark">
    <color rgba="0.3 0.3 0.3 1.0" />
  </material>
  <material name="light_black">
    <color rgba="0.4 0.4 0.4 1.0" />
  </material>

  <material name="blue">
    <color rgba="0.0 0.0 0.8 1.0" />
  </material>

  <material name="green">
    <color rgba="0.0 0.8 0.0 1.0" />
  </material>

  <material name="grey">
    <color rgba="0.5 0.5 0.5 1.0" />
  </material>

  <material name="orange">
    <color rgba="${255/255} ${108/255} ${10/255} 1.0" />
  </material>

  <material name="brown">
    <color rgba="${222/255} ${207/255} ${195/255} 1.0" />
  </material>

  <material name="red">
    <color rgba="0.8 0.0 0.0 1.0" />
  </material>

  <material name="white">
    <color rgba="1.0 1.0 1.0 1.0" />
  </material> -->

  

</robot>